Workbook
Name GeoRegions: #REF!
Name GeoRegions: #REF!
Name GeoRegions: #REF!
Name GeoRegions: #REF!
Name MPOField: #REF!
Name MPOField: #REF!
Name MPOField: #REF!
Name MPOField: #REF!
Name vvf: #REF!
Name vvf: #REF!
Name vvf: #REF!

Sheet EvOSys
A2: Average WeekdayBoardings by Mode/Agency
A3: Mode/Agency | C3: 2024 Modeled | D3: 2045 Modeled | E3: 2045 Growth | F3: 2050 Modeled | G3: 2050 Growth
A4: MBTA Heavy Rail | C4: 291132 | D4: ='EvO10.01-2045'!$M274 -> 362802 | E4: =(D4-C4)/C4 -> 0.24617699 | F4: ='EvO10.01-2050'!M274 -> 370339 | G4: =(F4-C4)/C4 -> 0.27206559
A5: MBTA Light Rail | C5: 115221 | D5: ='EvO10.01-2045'!$M275 -> 129932 | E5: =(D5-C5)/C5 -> 0.12767638 | F5: ='EvO10.01-2050'!M275 -> 140600 | G5: =(F5-C5)/C5 -> 0.22026367
A6: MBTA Commuter Rail | C6: 112438 | D6: ='EvO10.01-2045'!$M276 -> 179103 | E6: =(D6-C6)/C6 -> 0.59290453 | F6: ='EvO10.01-2050'!M276 -> 179697 | G6: =(F6-C6)/C6 -> 0.59818745
A7: MBTA Ferry | C7: 4999 | D7: ='EvO10.01-2045'!$M277 -> 3569 | E7: =(D7-C7)/C7 -> -0.28605721 | F7: ='EvO10.01-2050'!M277 -> 3522 | G7: =(F7-C7)/C7 -> -0.29545909
A8: MBTA Silver Line | C8: 33237 | D8: ='EvO10.01-2045'!$M278 -> 49244 | E8: =(D8-C8)/C8 -> 0.48160183 | F8: ='EvO10.01-2050'!M278 -> 49623 | G8: =(F8-C8)/C8 -> 0.49300478
A9: MBTA Bus | C9: 173337 | D9: ='EvO10.01-2045'!$M279 -> 259261 | E9: =(D9-C9)/C9 -> 0.4957049 | F9: ='EvO10.01-2050'!M279 -> 263916 | G9: =(F9-C9)/C9 -> 0.5225601
A10: MBTA Key Bus | C10: 119426 | D10: ='EvO10.01-2045'!$M280 -> 174188 | E10: =(D10-C10)/C10 -> 0.45854337 | F10: ='EvO10.01-2050'!M280 -> 182324 | G10: =(F10-C10)/C10 -> 0.52666923
A11: MBTA Express Bus | C11: 7100 | D11: ='EvO10.01-2045'!$M281 -> 6962 | E11: =(D11-C11)/C11 -> -0.01943662 | F11: ='EvO10.01-2050'!M281 -> 6955 | G11: =(F11-C11)/C11 -> -0.020422535
A12: CATA Bus | C12: 632 | D12: ='EvO10.01-2045'!$M282 -> 636 | E12: =(D12-C12)/C12 -> 0.0063291139 | F12: ='EvO10.01-2050'!M282 -> 640 | G12: =(F12-C12)/C12 -> 0.012658228
A13: MWRTA Bus | C13: 2472 | D13: ='EvO10.01-2045'!$M283 -> 2826 | E13: =(D13-C13)/C13 -> 0.14320388 | F13: ='EvO10.01-2050'!M283 -> 2833 | G13: =(F13-C13)/C13 -> 0.1460356
A14: MVRTA Bus | C14: 7461 | D14: ='EvO10.01-2045'!$M284 -> 8230 | E14: =(D14-C14)/C14 -> 0.10306929 | F14: ='EvO10.01-2050'!M284 -> 8315 | G14: =(F14-C14)/C14 -> 0.11446187
A15: BAT Bus | C15: 12052 | D15: ='EvO10.01-2045'!$M285 -> 14549 | E15: =(D15-C15)/C15 -> 0.20718553 | F15: ='EvO10.01-2050'!M285 -> 14598 | G15: =(F15-C15)/C15 -> 0.21125124
A16: Total | C16: 879507 | D16: =SUM(D4:D15) -> 1191302 | E16: =(D16-C16)/C16 -> 0.35451111 | F16: =SUM(F4:F15) -> 1223362 | G16: =(F16-C16)/C16 -> 0.39096335
A39: Transit Linked Trips Detail | F39: STOPS (Adjusted)
A40: FG Only | F40: =#REF! -> #REF!
A41: FG + Bus | F41: =#REF! -> #REF!
A42: FG All | F42: =#REF! -> #REF!
A43: Bus Only | F43: =#REF! -> #REF!
A45: PnR - FG Only | F45: =#REF! -> #REF!
A46: PnR - FG + Bus | F46: =#REF! -> #REF!
A47: PnR - FG All | F47: =#REF! -> #REF!
A48: PnR - Bus Only | F48: =#REF! -> #REF!
A50: KnR - FG Only | F50: =#REF! -> #REF!
A51: KnR - FG + Bus | F51: =#REF! -> #REF!
A52: KnR - FG All | F52: =#REF! -> #REF!
A53: KnR - Bus Only | F53: =#REF! -> #REF!

Sheet EvO10.01-2045
A2: Table 10.01 (Route Level Ridership by Access Mode) | L2: Table10.01
J4: 8 | K4: 9 | L4: 10
F5: Observed | J5: Estimated | O5: route_id | P5: route_long_name | Q5: Group | R5: Ridership | S5: route_gtfs | T5: Mode
A6: Route_ID | B6: Route Name | C6: Route # | D6: Agency | E6: Mode | F6: WLK | G6: KNR | H6: PNR | I6: ALL | J6: WLK | K6: KNR | L6: PNR | M6: ALL | O6: Red&T | P6: Red Line | Q6: 1 | R6: 133995 | S6: Red | T6: HR
O7: Mattapan&T | P7: Mattapan Trolley | Q7: 2 | R7: 4523 | S7: Mattapan | T7: LR
A8: Red&T | B8: Red Line | C8: Red | D8: MBTA HRT | E8: HR | I8: =VLOOKUP(A8,$O$5:$R$279,4,0) -> 133995 | J8: 123529 | K8: 9486 | L8: 21558 | M8: =SUM(J8:L8) -> 154573 | O8: Orange&T | P8: Orange Line | Q8: 3 | R8: 115769 | S8: Orange | T8: HR
A9: Orange&T | B9: Orange Line | C9: Orange | D9: MBTA HRT | E9: HR | I9: =VLOOKUP(A9,$O$5:$R$279,4,0) -> 115769 | J9: 112124 | K9: 10039 | L9: 23190 | M9: =SUM(J9:L9) -> 145353 | O9: Green-B&T | P9: Green Line B | Q9: 4 | R9: 113376 | S9: Green-B | T9: LRT
A10: Blue&T | B10: Blue Line | C10: Blue | D10: MBTA HRT | E10: HR | I10: =VLOOKUP(A10,$O$5:$R$279,4,0) -> 47213 | J10: 49792 | K10: 3359 | L10: 9725 | M10: =SUM(J10:L10) -> 62876 | O10: Green-C&T | P10: Green Line C | Q10: 4 | R10: 0 | S10: Green-C | T10: LRT
A11: Mattapan&T | B11: Mattapan Trolley | C11: Mattapan | D11: MBTA LRT | E11: LRT | I11: =VLOOKUP(A11,$O$5:$R$279,4,0) -> 4523 | J11: 3957 | K11: 331 | L11: 1147 | M11: =SUM(J11:L11) -> 5435 | O11: Green-D&T | P11: Green Line D | Q11: 4 | R11: 0 | S11: Green-D | T11: LRT
A12: Green-B&T | B12: Green Line B | C12: Green-B | D12: MBTA LRT | E12: LRT | I12: =VLOOKUP(A12,$O$5:$R$279,4,0) -> 113376 | J12: 30461 | K12: 1605 | L12: 2316 | M12: =SUM(J12:L12) -> 34382 | O12: Green-E&T | P12: Green Line E | Q12: 4 | R12: 0 | S12: Green-E | T12: LRT
A13: Green-C&T | B13: Green Line C | C13: Green-C | D13: MBTA LRT | E13: LRT | I13: =VLOOKUP(A13,$O$5:$R$279,4,0) -> 0 | J13: 19442 | K13: 1052 | L13: 1574 | M13: =SUM(J13:L13) -> 22068 | O13: Blue&T | P13: Blue Line | Q13: 8 | R13: 47213 | S13: Blue | T13: HR
A14: Green-D&T | B14: Green Line D | C14: Green-D | D14: MBTA LRT | E14: LRT | I14: =VLOOKUP(A14,$O$5:$R$279,4,0) -> 0 | J14: 27422 | K14: 2136 | L14: 4568 | M14: =SUM(J14:L14) -> 34126 | O14: 741&T | P14: Logan Airport Terminals - South Station | Q14: 9 | R14: 6310 | S14: 741 | T14: MBTA SL Bus
A15: Green-E&T | B15: Green Line E | C15: Green-E | D15: MBTA LRT | E15: LRT | I15: =VLOOKUP(A15,$O$5:$R$279,4,0) -> 0 | J15: 28554 | K15: 1963 | L15: 3404 | M15: =SUM(J15:L15) -> 33921 | O15: 742&T | P15: Design Center - South Station | Q15: 10 | R15: 3501 | S15: 742 | T15: MBTA SL Bus
A16: CR-Fairmount&T | B16: Fairmount Line | C16: CR-Fairmount | D16: MBTA Commuter Rail | E16: CR | I16: =VLOOKUP(A16,$O$5:$R$279,4,0) -> 5044 | J16: 9991 | K16: 1116 | L16: 698 | M16: =SUM(J16:L16) -> 11805 | O16: 743&T | P16: Chelsea Station - South Station | Q16: 11 | R16: 9569 | S16: 743 | T16: MBTA SL Bus
A17: CR-Fitchburg&T | B17: Fitchburg Line | C17: CR-Fitchburg | D17: MBTA Commuter Rail | E17: CR | I17: =VLOOKUP(A17,$O$5:$R$279,4,0) -> 7319 | J17: 7408 | K17: 2556 | L17: 12129 | M17: =SUM(J17:L17) -> 22093 | O17: 751&T | P17: Nubian Station - South Station | Q17: 12 | R17: 4618 | S17: 751 | T17: MBTA SL Bus
A18: CR-Worcester&T | B18: Framingham/Worcester Line | C18: CR-Worcester | D18: MBTA Commuter Rail | E18: CR | I18: =VLOOKUP(A18,$O$5:$R$279,4,0) -> 17120 | J18: 17235 | K18: 5034 | L18: 11126 | M18: =SUM(J18:L18) -> 33395 | O18: 749&T | P18: Nubian Station - Temple Place | Q18: 13 | R18: 8333 | S18: 749 | T18: MBTA SL Bus
A19: CR-Franklin&T | B19: Franklin/Foxboro Line | C19: CR-Franklin | D19: MBTA Commuter Rail | E19: CR | I19: =VLOOKUP(A19,$O$5:$R$279,4,0) -> 11914 | J19: 3851 | K19: 1058 | L19: 7679 | M19: =SUM(J19:L19) -> 12588 | O19: 746&T | P19: Silver Line Way - South Station | Q19: 14 | R19: 905 | S19: 746 | T19: MBTA SL Bus
A20: CR-Greenbush&T | B20: Greenbush Line | C20: CR-Greenbush | D20: MBTA Commuter Rail | E20: CR | I20: =VLOOKUP(A20,$O$5:$R$279,4,0) -> 4286 | J20: 1065 | K20: 259 | L20: 5014 | M20: =SUM(J20:L20) -> 6338 | O20: CR-Fairmount&T | P20: Fairmount Line | Q20: 15 | R20: 5044 | S20: CR-Fairmount | T20: CR
A21: CR-Haverhill&T | B21: Haverhill Line | C21: CR-Haverhill | D21: MBTA Commuter Rail | E21: CR | I21: =VLOOKUP(A21,$O$5:$R$279,4,0) -> 4418 | J21: 3767 | K21: 714 | L21: 7563 | M21: =SUM(J21:L21) -> 12044 | O21: CR-Fitchburg&T | P21: Fitchburg Line | Q21: 16 | R21: 7319 | S21: CR-Fitchburg | T21: CR
A22: CR-Kingston&T | B22: Kingston Line | C22: CR-Kingston | D22: MBTA Commuter Rail | E22: CR | I22: =VLOOKUP(A22,$O$5:$R$279,4,0) -> 6084 | J22: 626 | K22: 448 | L22: 7119 | M22: =SUM(J22:L22) -> 8193 | O22: CR-Worcester&T | P22: Framingham/Worcester Line | Q22: 17 | R22: 17120 | S22: CR-Worcester | T22: CR
A23: CR-Lowell&T | B23: Lowell Line | C23: CR-Lowell | D23: MBTA Commuter Rail | E23: CR | I23: =VLOOKUP(A23,$O$5:$R$279,4,0) -> 7215 | J23: 2419 | K23: 647 | L23: 7250 | M23: =SUM(J23:L23) -> 10316 | O23: CR-Franklin&T | P23: Franklin/Foxboro Line | Q23: 18 | R23: 11914 | S23: CR-Franklin | T23: CR
A24: CR-Middleborough&T | B24: Middleborough/Lakeville Line | C24: CR-Middleborough | D24: MBTA Commuter Rail | E24: CR | I24: =VLOOKUP(A24,$O$5:$R$279,4,0) -> 7641 | J24: 4021 | K24: 833 | L24: 2772 | M24: =SUM(J24:L24) -> 7626 | O24: CR-Greenbush&T | P24: Greenbush Line | Q24: 19 | R24: 4286 | S24: CR-Greenbush | T24: CR
A25: CR-Needham&T | B25: Needham Line | C25: CR-Needham | D25: MBTA Commuter Rail | E25: CR | I25: =VLOOKUP(A25,$O$5:$R$279,4,0) -> 6948 | J25: 6594 | K25: 612 | L25: 1677 | M25: =SUM(J25:L25) -> 8883 | O25: CR-Haverhill&T | P25: Haverhill Line | Q25: 20 | R25: 4418 | S25: CR-Haverhill | T25: CR
A26: CR-Newburyport&T | B26: Newburyport/Rockport Line | C26: CR-Newburyport | D26: MBTA Commuter Rail | E26: CR | I26: =VLOOKUP(A26,$O$5:$R$279,4,0) -> 11907 | J26: 10467 | K26: 1452 | L26: 8331 | M26: =SUM(J26:L26) -> 20250 | O26: CR-Kingston&T | P26: Kingston Line | Q26: 21 | R26: 6084 | S26: CR-Kingston | T26: CR
A27: CR-Providence&T | B27: Providence/Stoughton Line | C27: CR-Providence | D27: MBTA Commuter Rail | E27: CR | I27: =VLOOKUP(A27,$O$5:$R$279,4,0) -> 21859 | J27: 5675 | K27: 3891 | L27: 16006 | M27: =SUM(J27:L27) -> 25572 | O27: CR-Lowell&T | P27: Lowell Line | Q27: 22 | R27: 7215 | S27: CR-Lowell | T27: CR
A28: CR-Foxboro&T | B28: Foxboro Event Service | C28: CR-Foxboro | D28: MBTA Commuter Rail | E28: CR | I28: =VLOOKUP(A28,$O$5:$R$279,4,0) -> 0 | M28: =SUM(J28:L28) -> 0 | O28: CR-Middleborough&T | P28: Middleborough/Lakeville Line | Q28: 23 | R28: 7641 | S28: CR-Middleborough | T28: CR
A29: CapeFlyer&T | B29: CapeFLYER | C29: CapeFlyer | D29: MBTA Commuter Rail | E29: CR | I29: =VLOOKUP(A29,$O$5:$R$279,4,0) -> 0 | M29: =SUM(J29:L29) -> 0 | O29: CR-Needham&T | P29: Needham Line | Q29: 24 | R29: 6948 | S29: CR-Needham | T29: CR
A30: Boat-F4&T | B30: Charlestown Ferry | C30: Boat-F4 | D30: MBTA Ferry | E30: Ferry | I30: =VLOOKUP(A30,$O$5:$R$279,4,0) -> 1089 | J30: 1233 | K30: 93 | L30: 4 | M30: =SUM(J30:L30) -> 1330 | O30: CR-Newburyport&T | P30: Newburyport/Rockport Line | Q30: 25 | R30: 11907 | S30: CR-Newburyport | T30: CR
A31: Boat-F1&T | B31: Hingham/Hull Ferry | C31: Boat-F1 | D31: MBTA Ferry | E31: Ferry | I31: =VLOOKUP(A31,$O$5:$R$279,4,0) -> 3625 | J31: 41 | K31: 71 | L31: 1904 | M31: =SUM(J31:L31) -> 2016 | O31: CR-Providence&T | P31: Providence/Stoughton Line | Q31: 26 | R31: 21859 | S31: CR-Providence | T31: CR
A32: Boat-EastBoston&T | B32: East Boston Ferry | C32: Boat-EastBoston | D32: MBTA Ferry | E32: Ferry | I32: =VLOOKUP(A32,$O$5:$R$279,4,0) -> 283 | J32: 0 | K32: 0 | L32: 0 | M32: =SUM(J32:L32) -> 0 | O32: CR-Foxboro&T | P32: Foxboro Event Service | Q32: 27 | R32: 0 | S32: CR-Foxboro | T32: CR
A33: Boat-Lynn&T | B33: Lynn Ferry | C33: Boat-Lynn | D33: MBTA Ferry | E33: Ferry | I33: =VLOOKUP(A33,$O$5:$R$279,4,0) -> 189 | J33: 7 | K33: 22 | L33: 0 | M33: =SUM(J33:L33) -> 29 | O33: CapeFlyer&T | P33: CapeFLYER | Q33: 28 | R33: 0 | S33: CapeFlyer | T33: CR
A34: Boat-F6&T | B34: Winthrop/Quincy Ferry | C34: Boat-F6 | D34: MBTA Ferry | E34: Ferry | I34: =VLOOKUP(A34,$O$5:$R$279,4,0) -> 224 | J34: 170 | K34: 14 | L34: 10 | M34: =SUM(J34:L34) -> 194 | O34: Boat-F4&T | P34: Charlestown Ferry | Q34: 29 | R34: 1089 | S34: Boat-F4 | T34: Ferry
A35: 741&T | B35: Logan Airport Terminals - South Station | C35: 741 | D35: MBTA Key Bus (SL) | E35: Silver Line | I35: =VLOOKUP(A35,$O$5:$R$279,4,0) -> 6310 | J35: 11592 | K35: 523 | L35: 896 | M35: =SUM(J35:L35) -> 13011 | O35: Boat-F1&T | P35: Hingham/Hull Ferry | Q35: 30 | R35: 3625 | S35: Boat-F1 | T35: Ferry
A36: 742&T | B36: Design Center - South Station | C36: 742 | D36: MBTA Key Bus (SL) | E36: Silver Line | I36: =VLOOKUP(A36,$O$5:$R$279,4,0) -> 3501 | J36: 12128 | K36: 249 | L36: 909 | M36: =SUM(J36:L36) -> 13286 | O36: Boat-EastBoston&T | P36: East Boston Ferry | Q36: 31 | R36: 283 | S36: Boat-EastBoston | T36: Ferry
A37: 743&T | B37: Chelsea Station - South Station | C37: 743 | D37: MBTA Key Bus (SL) | E37: Silver Line | I37: =VLOOKUP(A37,$O$5:$R$279,4,0) -> 9569 | J37: 9091 | K37: 185 | L37: 913 | M37: =SUM(J37:L37) -> 10189 | O37: Boat-Lynn&T | P37: Lynn Ferry | Q37: 32 | R37: 189 | S37: Boat-Lynn | T37: Ferry
A38: 751&T | B38: Nubian Station - South Station | C38: 751 | D38: MBTA Key Bus (SL) | E38: Silver Line | I38: =VLOOKUP(A38,$O$5:$R$279,4,0) -> 4618 | J38: 0 | K38: 0 | L38: 0 | M38: =SUM(J38:L38) -> 0 | O38: Boat-F6&T | P38: Winthrop/Quincy Ferry | Q38: 33 | R38: 224 | S38: Boat-F6 | T38: Ferry
A39: 749&T | B39: Nubian Station - Temple Place | C39: 749 | D39: MBTA Key Bus (SL) | E39: Silver Line | I39: =VLOOKUP(A39,$O$5:$R$279,4,0) -> 8333 | J39: 12610 | K39: 46 | L39: 102 | M39: =SUM(J39:L39) -> 12758 | O39: 1&T | P39: Harvard Square - Nubian Station | Q39: 34 | R39: 9490 | S39: 1 | T39: MBTA Bus
A40: 746&T | B40: Silver Line Way - South Station | C40: 746 | D40: MBTA Key Bus (SL) | E40: Silver Line | I40: =VLOOKUP(A40,$O$5:$R$279,4,0) -> 905 | J40: 0 | K40: 0 | L40: 0 | M40: =SUM(J40:L40) -> 0 | O40: 4&T | P40: North Station - Design Center | Q40: 35 | R40: 261 | S40: 4 | T40: MBTA Bus
A41: 1&T | B41: Harvard Square - Nubian Station | C41: 1 | D41: MBTA Key Bus | E41: MBTA Key Bus | I41: =VLOOKUP(A41,$O$5:$R$279,4,0) -> 9490 | J41: 11833 | K41: 47 | L41: 107 | M41: =SUM(J41:L41) -> 11987 | O41: 7&T | P41: City Point - Otis Street & Summer Street | Q41: 36 | R41: 2869 | S41: 7 | T41: MBTA Bus
A42: 15&T | B42: Fields Corner Station or St Peter's Square - Ruggles Station | C42: 15 | D42: MBTA Key Bus | E42: MBTA Key Bus | I42: =VLOOKUP(A42,$O$5:$R$279,4,0) -> 5538 | J42: 9102 | K42: 17 | L42: 23 | M42: =SUM(J42:L42) -> 9142 | O42: 8&T | P42: Harbor Point - Kenmore Station | Q42: 37 | R42: 2874 | S42: 8 | T42: MBTA Bus
...

Sheet EvO10.01-2050
A2: Table 10.01 (Route Level Ridership by Access Mode) | L2: Table10.01
J4: 8 | K4: 9 | L4: 10
F5: Observed | J5: Estimated | N5: Difference | R5: % | T5: route_id | U5: route_long_name | V5: Group | W5: Ridership | X5: route_gtfs | Y5: Mode
A6: Route_ID | B6: Route Name | C6: Route # | D6: Agency | E6: Mode | F6: WLK | G6: KNR | H6: PNR | I6: ALL | J6: WLK | K6: KNR | L6: PNR | M6: ALL | N6: WLK | O6: KNR | P6: PNR | Q6: ALL | R6: Diff | T6: Red&T | U6: Red Line | V6: 1 | W6: 133995 | X6: Red | Y6: HR
T7: Mattapan&T | U7: Mattapan Trolley | V7: 2 | W7: 4523 | X7: Mattapan | Y7: LR
A8: Red&T | B8: Red Line | C8: Red | D8: MBTA HRT | E8: HR | I8: =VLOOKUP(A8,$T$5:$W$279,4,0) -> 133995 | J8: 125200 | K8: 9603 | L8: 21472 | M8: =SUM(J8:L8) -> 156275 | Q8: =M8-I8 -> 22280 | R8: =Q8/I8 -> 0.16627486 | T8: Orange&T | U8: Orange Line | V8: 3 | W8: 115769 | X8: Orange | Y8: HR
A9: Orange&T | B9: Orange Line | C9: Orange | D9: MBTA HRT | E9: HR | I9: =VLOOKUP(A9,$T$5:$W$279,4,0) -> 115769 | J9: 112697 | K9: 10130 | L9: 23095 | M9: =SUM(J9:L9) -> 145922 | Q9: =M9-I9 -> 30153 | R9: =Q9/I9 -> 0.26045833 | T9: Green-B&T | U9: Green Line B | V9: 4 | W9: 113376 | X9: Green-B | Y9: LRT
A10: Blue&T | B10: Blue Line | C10: Blue | D10: MBTA HRT | E10: HR | I10: =VLOOKUP(A10,$T$5:$W$279,4,0) -> 47213 | J10: 55348 | K10: 3487 | L10: 9307 | M10: =SUM(J10:L10) -> 68142 | Q10: =M10-I10 -> 20929 | R10: =Q10/I10 -> 0.44328892 | T10: Green-C&T | U10: Green Line C | V10: 4 | W10: 0 | X10: Green-C | Y10: LRT
A11: Mattapan&T | B11: Mattapan Trolley | C11: Mattapan | D11: MBTA LRT | E11: LRT | I11: =VLOOKUP(A11,$T$5:$W$279,4,0) -> 4523 | J11: 3957 | K11: 337 | L11: 1141 | M11: =SUM(J11:L11) -> 5435 | Q11: =M11-I11 -> 912 | R11: =Q11/I11 -> 0.20163608 | T11: Green-D&T | U11: Green Line D | V11: 4 | W11: 0 | X11: Green-D | Y11: LRT
A12: Green-B&T | B12: Green Line B | C12: Green-B | D12: MBTA LRT | E12: LRT | I12: =VLOOKUP(A12,$T$5:$W$279,4,0) -> 113376 | J12: 40261 | K12: 1852 | L12: 2401 | M12: =SUM(J12:L12) -> 44514 | Q12: =SUM(M12:M15)-I12 -> 21789 | R12: =Q12/I12 -> 0.19218353 | T12: Green-E&T | U12: Green Line E | V12: 4 | W12: 0 | X12: Green-E | Y12: LRT
A13: Green-C&T | B13: Green Line C | C13: Green-C | D13: MBTA LRT | E13: LRT | I13: =VLOOKUP(A13,$T$5:$W$279,4,0) -> 0 | J13: 19541 | K13: 1057 | L13: 1502 | M13: =SUM(J13:L13) -> 22100 | T13: Blue&T | U13: Blue Line | V13: 8 | W13: 47213 | X13: Blue | Y13: HR
A14: Green-D&T | B14: Green Line D | C14: Green-D | D14: MBTA LRT | E14: LRT | I14: =VLOOKUP(A14,$T$5:$W$279,4,0) -> 0 | J14: 27763 | K14: 2150 | L14: 4532 | M14: =SUM(J14:L14) -> 34445 | T14: 741&T | U14: Logan Airport Terminals - South Station | V14: 9 | W14: 6310 | X14: 741 | Y14: MBTA SL Bus
A15: Green-E&T | B15: Green Line E | C15: Green-E | D15: MBTA LRT | E15: LRT | I15: =VLOOKUP(A15,$T$5:$W$279,4,0) -> 0 | J15: 28753 | K15: 1964 | L15: 3389 | M15: =SUM(J15:L15) -> 34106 | T15: 742&T | U15: Design Center - South Station | V15: 10 | W15: 3501 | X15: 742 | Y15: MBTA SL Bus
A16: CR-Fairmount&T | B16: Fairmount Line | C16: CR-Fairmount | D16: MBTA Commuter Rail | E16: CR | I16: =VLOOKUP(A16,$T$5:$W$279,4,0) -> 5044 | J16: 10120 | K16: 1135 | L16: 706 | M16: =SUM(J16:L16) -> 11961 | Q16: =M16-I16 -> 6917 | R16: =Q16/I16 -> 1.3713323 | T16: 743&T | U16: Chelsea Station - South Station | V16: 11 | W16: 9569 | X16: 743 | Y16: MBTA SL Bus
A17: CR-Fitchburg&T | B17: Fitchburg Line | C17: CR-Fitchburg | D17: MBTA Commuter Rail | E17: CR | I17: =VLOOKUP(A17,$T$5:$W$279,4,0) -> 7319 | J17: 7440 | K17: 2547 | L17: 12056 | M17: =SUM(J17:L17) -> 22043 | Q17: =M17-I17 -> 14724 | R17: =Q17/I17 -> 2.0117502 | T17: 751&T | U17: Nubian Station - South Station | V17: 12 | W17: 4618 | X17: 751 | Y17: MBTA SL Bus
A18: CR-Worcester&T | B18: Framingham/Worcester Line | C18: CR-Worcester | D18: MBTA Commuter Rail | E18: CR | I18: =VLOOKUP(A18,$T$5:$W$279,4,0) -> 17120 | J18: 17731 | K18: 5160 | L18: 11116 | M18: =SUM(J18:L18) -> 34007 | Q18: =M18-I18 -> 16887 | R18: =Q18/I18 -> 0.98639019 | T18: 749&T | U18: Nubian Station - Temple Place | V18: 13 | W18: 8333 | X18: 749 | Y18: MBTA SL Bus
A19: CR-Franklin&T | B19: Franklin/Foxboro Line | C19: CR-Franklin | D19: MBTA Commuter Rail | E19: CR | I19: =VLOOKUP(A19,$T$5:$W$279,4,0) -> 11914 | J19: 3883 | K19: 1063 | L19: 7663 | M19: =SUM(J19:L19) -> 12609 | Q19: =M19-I19 -> 695 | R19: =Q19/I19 -> 0.058334732 | T19: 746&T | U19: Silver Line Way - South Station | V19: 14 | W19: 905 | X19: 746 | Y19: MBTA SL Bus
A20: CR-Greenbush&T | B20: Greenbush Line | C20: CR-Greenbush | D20: MBTA Commuter Rail | E20: CR | I20: =VLOOKUP(A20,$T$5:$W$279,4,0) -> 4286 | J20: 1072 | K20: 258 | L20: 4965 | M20: =SUM(J20:L20) -> 6295 | Q20: =M20-I20 -> 2009 | R20: =Q20/I20 -> 0.46873542 | T20: CR-Fairmount&T | U20: Fairmount Line | V20: 15 | W20: 5044 | X20: CR-Fairmount | Y20: CR
A21: CR-Haverhill&T | B21: Haverhill Line | C21: CR-Haverhill | D21: MBTA Commuter Rail | E21: CR | I21: =VLOOKUP(A21,$T$5:$W$279,4,0) -> 4418 | J21: 3787 | K21: 719 | L21: 7547 | M21: =SUM(J21:L21) -> 12053 | Q21: =M21-I21 -> 7635 | R21: =Q21/I21 -> 1.7281575 | T21: CR-Fitchburg&T | U21: Fitchburg Line | V21: 16 | W21: 7319 | X21: CR-Fitchburg | Y21: CR
A22: CR-Kingston&T | B22: Kingston Line | C22: CR-Kingston | D22: MBTA Commuter Rail | E22: CR | I22: =VLOOKUP(A22,$T$5:$W$279,4,0) -> 6084 | J22: 625 | K22: 450 | L22: 7066 | M22: =SUM(J22:L22) -> 8141 | Q22: =M22-I22 -> 2057 | R22: =Q22/I22 -> 0.33809993 | T22: CR-Worcester&T | U22: Framingham/Worcester Line | V22: 17 | W22: 17120 | X22: CR-Worcester | Y22: CR
A23: CR-Lowell&T | B23: Lowell Line | C23: CR-Lowell | D23: MBTA Commuter Rail | E23: CR | I23: =VLOOKUP(A23,$T$5:$W$279,4,0) -> 7215 | J23: 2406 | K23: 645 | L23: 7172 | M23: =SUM(J23:L23) -> 10223 | Q23: =M23-I23 -> 3008 | R23: =Q23/I23 -> 0.41690922 | T23: CR-Franklin&T | U23: Franklin/Foxboro Line | V23: 18 | W23: 11914 | X23: CR-Franklin | Y23: CR
A24: CR-Middleborough&T | B24: Middleborough/Lakeville Line | C24: CR-Middleborough | D24: MBTA Commuter Rail | E24: CR | I24: =VLOOKUP(A24,$T$5:$W$279,4,0) -> 7641 | J24: 4081 | K24: 839 | L24: 2755 | M24: =SUM(J24:L24) -> 7675 | Q24: =M24-I24 -> 34 | R24: =Q24/I24 -> 0.0044496794 | T24: CR-Greenbush&T | U24: Greenbush Line | V24: 19 | W24: 4286 | X24: CR-Greenbush | Y24: CR
A25: CR-Needham&T | B25: Needham Line | C25: CR-Needham | D25: MBTA Commuter Rail | E25: CR | I25: =VLOOKUP(A25,$T$5:$W$279,4,0) -> 6948 | J25: 6657 | K25: 625 | L25: 1679 | M25: =SUM(J25:L25) -> 8961 | Q25: =M25-I25 -> 2013 | R25: =Q25/I25 -> 0.28972366 | T25: CR-Haverhill&T | U25: Haverhill Line | V25: 20 | W25: 4418 | X25: CR-Haverhill | Y25: CR
A26: CR-Newburyport&T | B26: Newburyport/Rockport Line | C26: CR-Newburyport | D26: MBTA Commuter Rail | E26: CR | I26: =VLOOKUP(A26,$T$5:$W$279,4,0) -> 11907 | J26: 10468 | K26: 1447 | L26: 8220 | M26: =SUM(J26:L26) -> 20135 | Q26: =M26-I26 -> 8228 | R26: =Q26/I26 -> 0.69102209 | T26: CR-Kingston&T | U26: Kingston Line | V26: 21 | W26: 6084 | X26: CR-Kingston | Y26: CR
A27: CR-Providence&T | B27: Providence/Stoughton Line | C27: CR-Providence | D27: MBTA Commuter Rail | E27: CR | I27: =VLOOKUP(A27,$T$5:$W$279,4,0) -> 21859 | J27: 5694 | K27: 3913 | L27: 15987 | M27: =SUM(J27:L27) -> 25594 | Q27: =M27-I27 -> 3735 | R27: =Q27/I27 -> 0.17086783 | T27: CR-Lowell&T | U27: Lowell Line | V27: 22 | W27: 7215 | X27: CR-Lowell | Y27: CR
A28: CR-Foxboro&T | B28: Foxboro Event Service | C28: CR-Foxboro | D28: MBTA Commuter Rail | E28: CR | I28: =VLOOKUP(A28,$T$5:$W$279,4,0) -> 0 | M28: =SUM(J28:L28) -> 0 | Q28: =M28-I28 -> 0 | R28: =Q28/I28 -> #DIV/0! | T28: CR-Middleborough&T | U28: Middleborough/Lakeville Line | V28: 23 | W28: 7641 | X28: CR-Middleborough | Y28: CR
A29: CapeFlyer&T | B29: CapeFLYER | C29: CapeFlyer | D29: MBTA Commuter Rail | E29: CR | I29: =VLOOKUP(A29,$T$5:$W$279,4,0) -> 0 | M29: =SUM(J29:L29) -> 0 | Q29: =M29-I29 -> 0 | R29: =Q29/I29 -> #DIV/0! | T29: CR-Needham&T | U29: Needham Line | V29: 24 | W29: 6948 | X29: CR-Needham | Y29: CR
A30: Boat-F4&T | B30: Charlestown Ferry | C30: Boat-F4 | D30: MBTA Ferry | E30: Ferry | I30: =VLOOKUP(A30,$T$5:$W$279,4,0) -> 1089 | J30: 1219 | K30: 93 | L30: 4 | M30: =SUM(J30:L30) -> 1316 | Q30: =M30-I30 -> 227 | R30: =Q30/I30 -> 0.20844812 | T30: CR-Newburyport&T | U30: Newburyport/Rockport Line | V30: 25 | W30: 11907 | X30: CR-Newburyport | Y30: CR
A31: Boat-F1&T | B31: Hingham/Hull Ferry | C31: Boat-F1 | D31: MBTA Ferry | E31: Ferry | I31: =VLOOKUP(A31,$T$5:$W$279,4,0) -> 3625 | J31: 40 | K31: 70 | L31: 1876 | M31: =SUM(J31:L31) -> 1986 | Q31: =M31-I31 -> -1639 | R31: =Q31/I31 -> -0.45213793 | T31: CR-Providence&T | U31: Providence/Stoughton Line | V31: 26 | W31: 21859 | X31: CR-Providence | Y31: CR
A32: Boat-EastBoston&T | B32: East Boston Ferry | C32: Boat-EastBoston | D32: MBTA Ferry | E32: Ferry | I32: =VLOOKUP(A32,$T$5:$W$279,4,0) -> 283 | J32: 0 | K32: 0 | L32: 0 | M32: =SUM(J32:L32) -> 0 | Q32: =M32-I32 -> -283 | R32: =Q32/I32 -> -1 | T32: CR-Foxboro&T | U32: Foxboro Event Service | V32: 27 | W32: 0 | X32: CR-Foxboro | Y32: CR
A33: Boat-Lynn&T | B33: Lynn Ferry | C33: Boat-Lynn | D33: MBTA Ferry | E33: Ferry | I33: =VLOOKUP(A33,$T$5:$W$279,4,0) -> 189 | J33: 7 | K33: 21 | L33: 0 | M33: =SUM(J33:L33) -> 28 | Q33: =M33-I33 -> -161 | R33: =Q33/I33 -> -0.85185185 | T33: CapeFlyer&T | U33: CapeFLYER | V33: 28 | W33: 0 | X33: CapeFlyer | Y33: CR
A34: Boat-F6&T | B34: Winthrop/Quincy Ferry | C34: Boat-F6 | D34: MBTA Ferry | E34: Ferry | I34: =VLOOKUP(A34,$T$5:$W$279,4,0) -> 224 | J34: 168 | K34: 14 | L34: 10 | M34: =SUM(J34:L34) -> 192 | Q34: =M34-I34 -> -32 | R34: =Q34/I34 -> -0.14285714 | T34: Boat-F4&T | U34: Charlestown Ferry | V34: 29 | W34: 1089 | X34: Boat-F4 | Y34: Ferry
A35: 741&T | B35: Logan Airport Terminals - South Station | C35: 741 | D35: MBTA Key Bus (SL) | E35: Silver Line | I35: =VLOOKUP(A35,$T$5:$W$279,4,0) -> 6310 | J35: 11722 | K35: 527 | L35: 901 | M35: =SUM(J35:L35) -> 13150 | Q35: =M35-I35 -> 6840 | R35: =Q35/I35 -> 1.0839937 | T35: Boat-F1&T | U35: Hingham/Hull Ferry | V35: 30 | W35: 3625 | X35: Boat-F1 | Y35: Ferry
A36: 742&T | B36: Design Center - South Station | C36: 742 | D36: MBTA Key Bus (SL) | E36: Silver Line | I36: =VLOOKUP(A36,$T$5:$W$279,4,0) -> 3501 | J36: 12171 | K36: 248 | L36: 900 | M36: =SUM(J36:L36) -> 13319 | Q36: =M36-I36 -> 9818 | R36: =Q36/I36 -> 2.8043416 | T36: Boat-EastBoston&T | U36: East Boston Ferry | V36: 31 | W36: 283 | X36: Boat-EastBoston | Y36: Ferry
A37: 743&T | B37: Chelsea Station - South Station | C37: 743 | D37: MBTA Key Bus (SL) | E37: Silver Line | I37: =VLOOKUP(A37,$T$5:$W$279,4,0) -> 9569 | J37: 8979 | K37: 185 | L37: 896 | M37: =SUM(J37:L37) -> 10060 | Q37: =M37-I37 -> 491 | R37: =Q37/I37 -> 0.051311527 | T37: Boat-Lynn&T | U37: Lynn Ferry | V37: 32 | W37: 189 | X37: Boat-Lynn | Y37: Ferry
A38: 751&T | B38: Nubian Station - South Station | C38: 751 | D38: MBTA Key Bus (SL) | E38: Silver Line | I38: =VLOOKUP(A38,$T$5:$W$279,4,0) -> 4618 | J38: 0 | K38: 0 | L38: 0 | M38: =SUM(J38:L38) -> 0 | Q38: =M38-I38 -> -4618 | R38: =Q38/I38 -> -1 | T38: Boat-F6&T | U38: Winthrop/Quincy Ferry | V38: 33 | W38: 224 | X38: Boat-F6 | Y38: Ferry
A39: 749&T | B39: Nubian Station - Temple Place | C39: 749 | D39: MBTA Key Bus (SL) | E39: Silver Line | I39: =VLOOKUP(A39,$T$5:$W$279,4,0) -> 8333 | J39: 12945 | K39: 47 | L39: 102 | M39: =SUM(J39:L39) -> 13094 | Q39: =M39-I39 -> 4761 | R39: =Q39/I39 -> 0.57134285 | T39: 1&T | U39: Harvard Square - Nubian Station | V39: 34 | W39: 9490 | X39: 1 | Y39: MBTA Bus
A40: 746&T | B40: Silver Line Way - South Station | C40: 746 | D40: MBTA Key Bus (SL) | E40: Silver Line | I40: =VLOOKUP(A40,$T$5:$W$279,4,0) -> 905 | J40: 0 | K40: 0 | L40: 0 | M40: =SUM(J40:L40) -> 0 | Q40: =M40-I40 -> -905 | R40: =Q40/I40 -> -1 | T40: 4&T | U40: North Station - Design Center | V40: 35 | W40: 261 | X40: 4 | Y40: MBTA Bus
A41: 1&T | B41: Harvard Square - Nubian Station | C41: 1 | D41: MBTA Key Bus | E41: MBTA Key Bus | I41: =VLOOKUP(A41,$T$5:$W$279,4,0) -> 9490 | J41: 12024 | K41: 47 | L41: 105 | M41: =SUM(J41:L41) -> 12176 | Q41: =M41-I41 -> 2686 | R41: =Q41/I41 -> 0.28303477 | T41: 7&T | U41: City Point - Otis Street & Summer Street | V41: 36 | W41: 2869 | X41: 7 | Y41: MBTA Bus
A42: 15&T | B42: Fields Corner Station or St Peter's Square - Ruggles Station | C42: 15 | D42: MBTA Key Bus | E42: MBTA Key Bus | I42: =VLOOKUP(A42,$T$5:$W$279,4,0) -> 5538 | J42: 9334 | K42: 18 | L42: 23 | M42: =SUM(J42:L42) -> 9375 | Q42: =M42-I42 -> 3837 | R42: =Q42/I42 -> 0.6928494 | T42: 8&T | U42: Harbor Point - Kenmore Station | V42: 37 | W42: 2874 | X42: 8 | Y42: MBTA Bus
...
